{"timestamp": "2025-05-23T17:03:13.988559", "level": "ERROR", "logger": "zeka.openrouter_client", "message": "OpenRouter API akış hatası: 'async for' requires an object with __aiter__ method, got Stream", "module": "openrouter_client", "function": "generate_stream", "line": 384, "exception": {"type": "TypeError", "message": "'async for' requires an object with __aiter__ method, got Stream", "traceback": "Traceback (most recent call last):\n  File \"C:\\Users\\tpoyr\\OneDrive\\Masaüstü\\z.e.k.a\\src\\core\\openrouter_client.py\", line 343, in generate_stream\n    async for chunk in stream:\n                       ^^^^^^\nTypeError: 'async for' requires an object with __aiter__ method, got Stream"}}
{"timestamp": "2025-05-23T17:03:14.020872", "level": "ERROR", "logger": "zeka.conversation_agent_streaming", "message": "Streaming sohbet hatası: [OPENROUTER_API_ERROR] Akış üretilemedi: 'async for' requires an object with __aiter__ method, got Stream", "module": "conversation_agent_streaming", "function": "_handle_chat_streaming", "line": 180, "exception": {"type": "OpenRouterAPIError", "message": "[OPENROUTER_API_ERROR] Akış üretilemedi: 'async for' requires an object with __aiter__ method, got Stream", "traceback": "Traceback (most recent call last):\n  File \"C:\\Users\\tpoyr\\OneDrive\\Masaüstü\\z.e.k.a\\src\\core\\openrouter_client.py\", line 343, in generate_stream\n    async for chunk in stream:\n                       ^^^^^^\nTypeError: 'async for' requires an object with __aiter__ method, got Stream\n\nDuring handling of the above exception, another exception occurred:\n\nTraceback (most recent call last):\n  File \"C:\\Users\\tpoyr\\OneDrive\\Masaüstü\\z.e.k.a\\src\\agents\\conversation_agent_streaming.py\", line 165, in _handle_chat_streaming\n    async for chunk in self.language_model.generate_stream(\n    ...<7 lines>...\n            yield chunk[\"content\"]\n  File \"C:\\Users\\tpoyr\\OneDrive\\Masaüstü\\z.e.k.a\\src\\core\\openrouter_client.py\", line 395, in generate_stream\n    raise OpenRouterAPIError(f\"Akış üretilemedi: {str(e)}\")\ncore.exceptions.OpenRouterAPIError: [OPENROUTER_API_ERROR] Akış üretilemedi: 'async for' requires an object with __aiter__ method, got Stream"}}
{"timestamp": "2025-05-23T19:25:56.265048", "level": "ERROR", "logger": "zeka.screen_perception", "message": "PyAutoGUI yüklü değil. 'pip install pyautogui' komutu ile yükleyin.", "module": "screen_perception", "function": "_check_dependencies", "line": 49}
{"timestamp": "2025-05-23T19:25:56.268031", "level": "ERROR", "logger": "zeka.screen_perception", "message": "PyTesseract yüklü değil. 'pip install pytesseract' komutu ile yükleyin.", "module": "screen_perception", "function": "_check_dependencies", "line": 72}
{"timestamp": "2025-05-23T19:25:56.270408", "level": "ERROR", "logger": "zeka.keyboard_control", "message": "PyAutoGUI yüklü değil. 'pip install pyautogui' komutu ile yükleyin.", "module": "keyboard_control", "function": "_check_dependencies", "line": 35}
{"timestamp": "2025-05-23T19:25:56.273273", "level": "ERROR", "logger": "zeka.app_control", "message": "PyAutoGUI yüklü değil. 'pip install pyautogui' komutu ile yükleyin.", "module": "app_control", "function": "_check_dependencies", "line": 35}
{"timestamp": "2025-05-23T19:25:56.275695", "level": "ERROR", "logger": "zeka.app_control", "message": "PyWinAuto yüklü değil. 'pip install pywinauto' komutu ile yükleyin.", "module": "app_control", "function": "_check_dependencies", "line": 45}
{"timestamp": "2025-05-23T19:34:54.400587", "level": "ERROR", "logger": "zeka.desktop_api", "message": "Pencereler listelenirken hata: 'ApplicationControl' object has no attribute 'get_active_window'", "module": "desktop", "function": "list_windows", "line": 253}
{"timestamp": "2025-05-23T19:35:44.606720", "level": "ERROR", "logger": "zeka.openrouter_client", "message": "OpenRouter API akış hatası: 'async for' requires an object with __aiter__ method, got Stream", "module": "openrouter_client", "function": "generate_stream", "line": 388, "exception": {"type": "TypeError", "message": "'async for' requires an object with __aiter__ method, got Stream", "traceback": "Traceback (most recent call last):\n  File \"C:\\Users\\tpoyr\\OneDrive\\Masaüstü\\z.e.k.a\\src\\core\\openrouter_client.py\", line 347, in generate_stream\n    async for chunk in stream:\n                       ^^^^^^\nTypeError: 'async for' requires an object with __aiter__ method, got Stream"}}
{"timestamp": "2025-05-23T19:35:44.610604", "level": "ERROR", "logger": "zeka.conversation_agent_streaming", "message": "Streaming sohbet hatası: [OPENROUTER_API_ERROR] Akış üretilemedi: 'async for' requires an object with __aiter__ method, got Stream", "module": "conversation_agent_streaming", "function": "_handle_chat_streaming", "line": 180, "exception": {"type": "OpenRouterAPIError", "message": "[OPENROUTER_API_ERROR] Akış üretilemedi: 'async for' requires an object with __aiter__ method, got Stream", "traceback": "Traceback (most recent call last):\n  File \"C:\\Users\\tpoyr\\OneDrive\\Masaüstü\\z.e.k.a\\src\\core\\openrouter_client.py\", line 347, in generate_stream\n    async for chunk in stream:\n                       ^^^^^^\nTypeError: 'async for' requires an object with __aiter__ method, got Stream\n\nDuring handling of the above exception, another exception occurred:\n\nTraceback (most recent call last):\n  File \"C:\\Users\\tpoyr\\OneDrive\\Masaüstü\\z.e.k.a\\src\\agents\\conversation_agent_streaming.py\", line 165, in _handle_chat_streaming\n    async for chunk in self.language_model.generate_stream(\n    ...<7 lines>...\n            yield chunk[\"content\"]\n  File \"C:\\Users\\tpoyr\\OneDrive\\Masaüstü\\z.e.k.a\\src\\core\\openrouter_client.py\", line 399, in generate_stream\n    raise OpenRouterAPIError(f\"Akış üretilemedi: {str(e)}\")\ncore.exceptions.OpenRouterAPIError: [OPENROUTER_API_ERROR] Akış üretilemedi: 'async for' requires an object with __aiter__ method, got Stream"}}
{"timestamp": "2025-05-23T19:43:32.292292", "level": "ERROR", "logger": "zeka.desktop_api", "message": "Pencereler listelenirken hata: 'ApplicationControl' object has no attribute 'get_active_window'", "module": "desktop", "function": "list_windows", "line": 253}
{"timestamp": "2025-05-23T20:01:13.862934", "level": "ERROR", "logger": "zeka.openrouter_client", "message": "OpenRouter API akış hatası: 'async for' requires an object with __aiter__ method, got Stream", "module": "openrouter_client", "function": "generate_stream", "line": 388, "exception": {"type": "TypeError", "message": "'async for' requires an object with __aiter__ method, got Stream", "traceback": "Traceback (most recent call last):\n  File \"C:\\Users\\tpoyr\\OneDrive\\Masaüstü\\z.e.k.a\\src\\core\\openrouter_client.py\", line 347, in generate_stream\n    async for chunk in stream:\n                       ^^^^^^\nTypeError: 'async for' requires an object with __aiter__ method, got Stream"}}
{"timestamp": "2025-05-23T20:01:13.866582", "level": "ERROR", "logger": "zeka.conversation_agent_streaming", "message": "Streaming sohbet hatası: [OPENROUTER_API_ERROR] Akış üretilemedi: 'async for' requires an object with __aiter__ method, got Stream", "module": "conversation_agent_streaming", "function": "_handle_chat_streaming", "line": 180, "exception": {"type": "OpenRouterAPIError", "message": "[OPENROUTER_API_ERROR] Akış üretilemedi: 'async for' requires an object with __aiter__ method, got Stream", "traceback": "Traceback (most recent call last):\n  File \"C:\\Users\\tpoyr\\OneDrive\\Masaüstü\\z.e.k.a\\src\\core\\openrouter_client.py\", line 347, in generate_stream\n    async for chunk in stream:\n                       ^^^^^^\nTypeError: 'async for' requires an object with __aiter__ method, got Stream\n\nDuring handling of the above exception, another exception occurred:\n\nTraceback (most recent call last):\n  File \"C:\\Users\\tpoyr\\OneDrive\\Masaüstü\\z.e.k.a\\src\\agents\\conversation_agent_streaming.py\", line 165, in _handle_chat_streaming\n    async for chunk in self.language_model.generate_stream(\n    ...<7 lines>...\n            yield chunk[\"content\"]\n  File \"C:\\Users\\tpoyr\\OneDrive\\Masaüstü\\z.e.k.a\\src\\core\\openrouter_client.py\", line 399, in generate_stream\n    raise OpenRouterAPIError(f\"Akış üretilemedi: {str(e)}\")\ncore.exceptions.OpenRouterAPIError: [OPENROUTER_API_ERROR] Akış üretilemedi: 'async for' requires an object with __aiter__ method, got Stream"}}
{"timestamp": "2025-05-23T20:18:10.646242", "level": "ERROR", "logger": "zeka.openrouter_client", "message": "OpenRouter API akış hatası: 'async for' requires an object with __aiter__ method, got Stream", "module": "openrouter_client", "function": "generate_stream", "line": 398, "exception": {"type": "TypeError", "message": "'async for' requires an object with __aiter__ method, got Stream", "traceback": "Traceback (most recent call last):\n  File \"C:\\Users\\tpoyr\\OneDrive\\Masaüstü\\z.e.k.a\\src\\core\\openrouter_client.py\", line 357, in generate_stream\n    async for chunk in stream:\n                       ^^^^^^\nTypeError: 'async for' requires an object with __aiter__ method, got Stream"}}
{"timestamp": "2025-05-23T20:18:10.650392", "level": "ERROR", "logger": "zeka.conversation_agent_streaming", "message": "Streaming sohbet hatası: [OPENROUTER_API_ERROR] Akış üretilemedi: 'async for' requires an object with __aiter__ method, got Stream", "module": "conversation_agent_streaming", "function": "_handle_chat_streaming", "line": 180, "exception": {"type": "OpenRouterAPIError", "message": "[OPENROUTER_API_ERROR] Akış üretilemedi: 'async for' requires an object with __aiter__ method, got Stream", "traceback": "Traceback (most recent call last):\n  File \"C:\\Users\\tpoyr\\OneDrive\\Masaüstü\\z.e.k.a\\src\\core\\openrouter_client.py\", line 357, in generate_stream\n    async for chunk in stream:\n                       ^^^^^^\nTypeError: 'async for' requires an object with __aiter__ method, got Stream\n\nDuring handling of the above exception, another exception occurred:\n\nTraceback (most recent call last):\n  File \"C:\\Users\\tpoyr\\OneDrive\\Masaüstü\\z.e.k.a\\src\\agents\\conversation_agent_streaming.py\", line 165, in _handle_chat_streaming\n    async for chunk in self.language_model.generate_stream(\n    ...<7 lines>...\n            yield chunk[\"content\"]\n  File \"C:\\Users\\tpoyr\\OneDrive\\Masaüstü\\z.e.k.a\\src\\core\\openrouter_client.py\", line 409, in generate_stream\n    raise OpenRouterAPIError(f\"Akış üretilemedi: {str(e)}\")\ncore.exceptions.OpenRouterAPIError: [OPENROUTER_API_ERROR] Akış üretilemedi: 'async for' requires an object with __aiter__ method, got Stream"}}
{"timestamp": "2025-05-23T20:18:24.019329", "level": "ERROR", "logger": "zeka.openrouter_client", "message": "OpenRouter API akış hatası: 'async for' requires an object with __aiter__ method, got Stream", "module": "openrouter_client", "function": "generate_stream", "line": 398, "exception": {"type": "TypeError", "message": "'async for' requires an object with __aiter__ method, got Stream", "traceback": "Traceback (most recent call last):\n  File \"C:\\Users\\tpoyr\\OneDrive\\Masaüstü\\z.e.k.a\\src\\core\\openrouter_client.py\", line 357, in generate_stream\n    async for chunk in stream:\n                       ^^^^^^\nTypeError: 'async for' requires an object with __aiter__ method, got Stream"}}
{"timestamp": "2025-05-23T20:18:24.022984", "level": "ERROR", "logger": "zeka.conversation_agent_streaming", "message": "Streaming sohbet hatası: [OPENROUTER_API_ERROR] Akış üretilemedi: 'async for' requires an object with __aiter__ method, got Stream", "module": "conversation_agent_streaming", "function": "_handle_chat_streaming", "line": 180, "exception": {"type": "OpenRouterAPIError", "message": "[OPENROUTER_API_ERROR] Akış üretilemedi: 'async for' requires an object with __aiter__ method, got Stream", "traceback": "Traceback (most recent call last):\n  File \"C:\\Users\\tpoyr\\OneDrive\\Masaüstü\\z.e.k.a\\src\\core\\openrouter_client.py\", line 357, in generate_stream\n    async for chunk in stream:\n                       ^^^^^^\nTypeError: 'async for' requires an object with __aiter__ method, got Stream\n\nDuring handling of the above exception, another exception occurred:\n\nTraceback (most recent call last):\n  File \"C:\\Users\\tpoyr\\OneDrive\\Masaüstü\\z.e.k.a\\src\\agents\\conversation_agent_streaming.py\", line 165, in _handle_chat_streaming\n    async for chunk in self.language_model.generate_stream(\n    ...<7 lines>...\n            yield chunk[\"content\"]\n  File \"C:\\Users\\tpoyr\\OneDrive\\Masaüstü\\z.e.k.a\\src\\core\\openrouter_client.py\", line 409, in generate_stream\n    raise OpenRouterAPIError(f\"Akış üretilemedi: {str(e)}\")\ncore.exceptions.OpenRouterAPIError: [OPENROUTER_API_ERROR] Akış üretilemedi: 'async for' requires an object with __aiter__ method, got Stream"}}
{"timestamp": "2025-05-23T20:21:29.316212", "level": "ERROR", "logger": "zeka.openrouter_client", "message": "OpenRouter API akış hatası: 'async for' requires an object with __aiter__ method, got Stream", "module": "openrouter_client", "function": "generate_stream", "line": 398, "exception": {"type": "TypeError", "message": "'async for' requires an object with __aiter__ method, got Stream", "traceback": "Traceback (most recent call last):\n  File \"C:\\Users\\tpoyr\\OneDrive\\Masaüstü\\z.e.k.a\\src\\core\\openrouter_client.py\", line 357, in generate_stream\n    async for chunk in stream:\n                       ^^^^^^\nTypeError: 'async for' requires an object with __aiter__ method, got Stream"}}
{"timestamp": "2025-05-23T20:21:29.319402", "level": "ERROR", "logger": "zeka.conversation_agent_streaming", "message": "Streaming sohbet hatası: [OPENROUTER_API_ERROR] Akış üretilemedi: 'async for' requires an object with __aiter__ method, got Stream", "module": "conversation_agent_streaming", "function": "_handle_chat_streaming", "line": 180, "exception": {"type": "OpenRouterAPIError", "message": "[OPENROUTER_API_ERROR] Akış üretilemedi: 'async for' requires an object with __aiter__ method, got Stream", "traceback": "Traceback (most recent call last):\n  File \"C:\\Users\\tpoyr\\OneDrive\\Masaüstü\\z.e.k.a\\src\\core\\openrouter_client.py\", line 357, in generate_stream\n    async for chunk in stream:\n                       ^^^^^^\nTypeError: 'async for' requires an object with __aiter__ method, got Stream\n\nDuring handling of the above exception, another exception occurred:\n\nTraceback (most recent call last):\n  File \"C:\\Users\\tpoyr\\OneDrive\\Masaüstü\\z.e.k.a\\src\\agents\\conversation_agent_streaming.py\", line 165, in _handle_chat_streaming\n    async for chunk in self.language_model.generate_stream(\n    ...<7 lines>...\n            yield chunk[\"content\"]\n  File \"C:\\Users\\tpoyr\\OneDrive\\Masaüstü\\z.e.k.a\\src\\core\\openrouter_client.py\", line 409, in generate_stream\n    raise OpenRouterAPIError(f\"Akış üretilemedi: {str(e)}\")\ncore.exceptions.OpenRouterAPIError: [OPENROUTER_API_ERROR] Akış üretilemedi: 'async for' requires an object with __aiter__ method, got Stream"}}
{"timestamp": "2025-05-24T15:30:31.392891", "level": "ERROR", "logger": "zeka.openai_client", "message": "OpenAI API anahtarı bulunamadı", "module": "openai_client", "function": "__init__", "line": 95}
{"timestamp": "2025-05-24T15:31:37.872752", "level": "ERROR", "logger": "zeka.openai_client", "message": "OpenAI API anahtarı bulunamadı", "module": "openai_client", "function": "__init__", "line": 95}
{"timestamp": "2025-05-24T15:36:30.126160", "level": "ERROR", "logger": "zeka.openai_client", "message": "openai API anahtarı bulunamadı", "module": "openai_client", "function": "__init__", "line": 117}
{"timestamp": "2025-05-24T15:36:30.185836", "level": "ERROR", "logger": "zeka.openai_client", "message": "openai API anahtarı bulunamadı", "module": "openai_client", "function": "__init__", "line": 117}
{"timestamp": "2025-05-24T15:36:30.692593", "level": "ERROR", "logger": "zeka.openai_client", "message": "openai API anahtarı bulunamadı", "module": "openai_client", "function": "__init__", "line": 117}
{"timestamp": "2025-05-24T15:36:33.694332", "level": "ERROR", "logger": "zeka.openai_client", "message": "openai API anahtarı bulunamadı", "module": "openai_client", "function": "__init__", "line": 117}
{"timestamp": "2025-05-24T15:36:37.666126", "level": "ERROR", "logger": "zeka.openai_client", "message": "openai API anahtarı bulunamadı", "module": "openai_client", "function": "__init__", "line": 117}
{"timestamp": "2025-05-24T15:36:41.660117", "level": "ERROR", "logger": "zeka.openai_client", "message": "openai API anahtarı bulunamadı", "module": "openai_client", "function": "__init__", "line": 117}
{"timestamp": "2025-05-24T15:36:45.674097", "level": "ERROR", "logger": "zeka.openai_client", "message": "openai API anahtarı bulunamadı", "module": "openai_client", "function": "__init__", "line": 117}
{"timestamp": "2025-05-24T15:36:49.673765", "level": "ERROR", "logger": "zeka.openai_client", "message": "openai API anahtarı bulunamadı", "module": "openai_client", "function": "__init__", "line": 117}
{"timestamp": "2025-05-24T15:37:17.666416", "level": "ERROR", "logger": "zeka.openai_client", "message": "openai API anahtarı bulunamadı", "module": "openai_client", "function": "__init__", "line": 117}
{"timestamp": "2025-05-24T15:37:21.671879", "level": "ERROR", "logger": "zeka.openai_client", "message": "openai API anahtarı bulunamadı", "module": "openai_client", "function": "__init__", "line": 117}
{"timestamp": "2025-05-24T15:41:57.044222", "level": "ERROR", "logger": "zeka.openai_client", "message": "Metin üretme hatası: Connection error.", "module": "openai_client", "function": "generate_text", "line": 223, "exception": {"type": "APIConnectionError", "message": "Connection error.", "traceback": "Traceback (most recent call last):\n  File \"C:\\Users\\tpoyr\\AppData\\Local\\Programs\\Python\\Python313\\Lib\\site-packages\\httpx\\_transports\\default.py\", line 101, in map_httpcore_exceptions\n    yield\n  File \"C:\\Users\\tpoyr\\AppData\\Local\\Programs\\Python\\Python313\\Lib\\site-packages\\httpx\\_transports\\default.py\", line 394, in handle_async_request\n    resp = await self._pool.handle_async_request(req)\n           ^^^^^^^^^^^^^^^^^^^^^^^^^^^^^^^^^^^^^^^^^^\n  File \"C:\\Users\\tpoyr\\AppData\\Local\\Programs\\Python\\Python313\\Lib\\site-packages\\httpcore\\_async\\connection_pool.py\", line 256, in handle_async_request\n    raise exc from None\n  File \"C:\\Users\\tpoyr\\AppData\\Local\\Programs\\Python\\Python313\\Lib\\site-packages\\httpcore\\_async\\connection_pool.py\", line 236, in handle_async_request\n    response = await connection.handle_async_request(\n               ^^^^^^^^^^^^^^^^^^^^^^^^^^^^^^^^^^^^^^\n        pool_request.request\n        ^^^^^^^^^^^^^^^^^^^^\n    )\n    ^\n  File \"C:\\Users\\tpoyr\\AppData\\Local\\Programs\\Python\\Python313\\Lib\\site-packages\\httpcore\\_async\\connection.py\", line 101, in handle_async_request\n    raise exc\n  File \"C:\\Users\\tpoyr\\AppData\\Local\\Programs\\Python\\Python313\\Lib\\site-packages\\httpcore\\_async\\connection.py\", line 78, in handle_async_request\n    stream = await self._connect(request)\n             ^^^^^^^^^^^^^^^^^^^^^^^^^^^^\n  File \"C:\\Users\\tpoyr\\AppData\\Local\\Programs\\Python\\Python313\\Lib\\site-packages\\httpcore\\_async\\connection.py\", line 124, in _connect\n    stream = await self._network_backend.connect_tcp(**kwargs)\n             ^^^^^^^^^^^^^^^^^^^^^^^^^^^^^^^^^^^^^^^^^^^^^^^^^\n  File \"C:\\Users\\tpoyr\\AppData\\Local\\Programs\\Python\\Python313\\Lib\\site-packages\\httpcore\\_backends\\auto.py\", line 31, in connect_tcp\n    return await self._backend.connect_tcp(\n           ^^^^^^^^^^^^^^^^^^^^^^^^^^^^^^^^\n    ...<5 lines>...\n    )\n    ^\n  File \"C:\\Users\\tpoyr\\AppData\\Local\\Programs\\Python\\Python313\\Lib\\site-packages\\httpcore\\_backends\\anyio.py\", line 113, in connect_tcp\n    with map_exceptions(exc_map):\n         ~~~~~~~~~~~~~~^^^^^^^^^\n  File \"C:\\Users\\tpoyr\\AppData\\Local\\Programs\\Python\\Python313\\Lib\\contextlib.py\", line 162, in __exit__\n    self.gen.throw(value)\n    ~~~~~~~~~~~~~~^^^^^^^\n  File \"C:\\Users\\tpoyr\\AppData\\Local\\Programs\\Python\\Python313\\Lib\\site-packages\\httpcore\\_exceptions.py\", line 14, in map_exceptions\n    raise to_exc(exc) from exc\nhttpcore.ConnectError: All connection attempts failed\n\nThe above exception was the direct cause of the following exception:\n\nTraceback (most recent call last):\n  File \"C:\\Users\\tpoyr\\AppData\\Local\\Programs\\Python\\Python313\\Lib\\site-packages\\openai\\_base_client.py\", line 1484, in request\n    response = await self._client.send(\n               ^^^^^^^^^^^^^^^^^^^^^^^^\n    ...<3 lines>...\n    )\n    ^\n  File \"C:\\Users\\tpoyr\\AppData\\Local\\Programs\\Python\\Python313\\Lib\\site-packages\\httpx\\_client.py\", line 1629, in send\n    response = await self._send_handling_auth(\n               ^^^^^^^^^^^^^^^^^^^^^^^^^^^^^^^\n    ...<4 lines>...\n    )\n    ^\n  File \"C:\\Users\\tpoyr\\AppData\\Local\\Programs\\Python\\Python313\\Lib\\site-packages\\httpx\\_client.py\", line 1657, in _send_handling_auth\n    response = await self._send_handling_redirects(\n               ^^^^^^^^^^^^^^^^^^^^^^^^^^^^^^^^^^^^\n    ...<3 lines>...\n    )\n    ^\n  File \"C:\\Users\\tpoyr\\AppData\\Local\\Programs\\Python\\Python313\\Lib\\site-packages\\httpx\\_client.py\", line 1694, in _send_handling_redirects\n    response = await self._send_single_request(request)\n               ^^^^^^^^^^^^^^^^^^^^^^^^^^^^^^^^^^^^^^^^\n  File \"C:\\Users\\tpoyr\\AppData\\Local\\Programs\\Python\\Python313\\Lib\\site-packages\\httpx\\_client.py\", line 1730, in _send_single_request\n    response = await transport.handle_async_request(request)\n               ^^^^^^^^^^^^^^^^^^^^^^^^^^^^^^^^^^^^^^^^^^^^^\n  File \"C:\\Users\\tpoyr\\AppData\\Local\\Programs\\Python\\Python313\\Lib\\site-packages\\httpx\\_transports\\default.py\", line 393, in handle_async_request\n    with map_httpcore_exceptions():\n         ~~~~~~~~~~~~~~~~~~~~~~~^^\n  File \"C:\\Users\\tpoyr\\AppData\\Local\\Programs\\Python\\Python313\\Lib\\contextlib.py\", line 162, in __exit__\n    self.gen.throw(value)\n    ~~~~~~~~~~~~~~^^^^^^^\n  File \"C:\\Users\\tpoyr\\AppData\\Local\\Programs\\Python\\Python313\\Lib\\site-packages\\httpx\\_transports\\default.py\", line 118, in map_httpcore_exceptions\n    raise mapped_exc(message) from exc\nhttpx.ConnectError: All connection attempts failed\n\nThe above exception was the direct cause of the following exception:\n\nTraceback (most recent call last):\n  File \"C:\\Users\\tpoyr\\OneDrive\\Masaüstü\\z.e.k.a\\src\\core\\openai_client.py\", line 204, in generate_text\n    response = await self.async_client.chat.completions.create(\n               ^^^^^^^^^^^^^^^^^^^^^^^^^^^^^^^^^^^^^^^^^^^^^^^^\n    ...<5 lines>...\n    )\n    ^\n  File \"C:\\Users\\tpoyr\\AppData\\Local\\Programs\\Python\\Python313\\Lib\\site-packages\\openai\\resources\\chat\\completions\\completions.py\", line 2028, in create\n    return await self._post(\n           ^^^^^^^^^^^^^^^^^\n    ...<45 lines>...\n    )\n    ^\n  File \"C:\\Users\\tpoyr\\AppData\\Local\\Programs\\Python\\Python313\\Lib\\site-packages\\openai\\_base_client.py\", line 1742, in post\n    return await self.request(cast_to, opts, stream=stream, stream_cls=stream_cls)\n           ^^^^^^^^^^^^^^^^^^^^^^^^^^^^^^^^^^^^^^^^^^^^^^^^^^^^^^^^^^^^^^^^^^^^^^^\n  File \"C:\\Users\\tpoyr\\AppData\\Local\\Programs\\Python\\Python313\\Lib\\site-packages\\openai\\_base_client.py\", line 1516, in request\n    raise APIConnectionError(request=request) from err\nopenai.APIConnectionError: Connection error."}}
{"timestamp": "2025-05-24T15:43:44.687678", "level": "ERROR", "logger": "zeka.openai_client", "message": "openai API anahtarı bulunamadı", "module": "openai_client", "function": "__init__", "line": 117}
{"timestamp": "2025-05-24T15:43:44.733595", "level": "ERROR", "logger": "zeka.openai_client", "message": "openai API anahtarı bulunamadı", "module": "openai_client", "function": "__init__", "line": 117}
{"timestamp": "2025-05-24T15:43:45.220423", "level": "ERROR", "logger": "zeka.openai_client", "message": "openai API anahtarı bulunamadı", "module": "openai_client", "function": "__init__", "line": 117}
{"timestamp": "2025-05-24T15:43:48.144583", "level": "ERROR", "logger": "zeka.openai_client", "message": "openai API anahtarı bulunamadı", "module": "openai_client", "function": "__init__", "line": 117}
{"timestamp": "2025-05-24T15:43:48.564481", "level": "ERROR", "logger": "zeka.openai_client", "message": "openai API anahtarı bulunamadı", "module": "openai_client", "function": "__init__", "line": 117}
{"timestamp": "2025-05-24T15:43:51.510776", "level": "ERROR", "logger": "zeka.openai_client", "message": "openai API anahtarı bulunamadı", "module": "openai_client", "function": "__init__", "line": 117}
{"timestamp": "2025-05-24T15:43:51.912920", "level": "ERROR", "logger": "zeka.openai_client", "message": "openai API anahtarı bulunamadı", "module": "openai_client", "function": "__init__", "line": 117}
{"timestamp": "2025-05-24T15:43:54.869051", "level": "ERROR", "logger": "zeka.openai_client", "message": "openai API anahtarı bulunamadı", "module": "openai_client", "function": "__init__", "line": 117}
{"timestamp": "2025-05-24T15:43:55.669790", "level": "ERROR", "logger": "zeka.openai_client", "message": "openai API anahtarı bulunamadı", "module": "openai_client", "function": "__init__", "line": 117}
{"timestamp": "2025-05-24T15:43:58.282347", "level": "ERROR", "logger": "zeka.openai_client", "message": "openai API anahtarı bulunamadı", "module": "openai_client", "function": "__init__", "line": 117}
{"timestamp": "2025-05-24T15:43:59.325540", "level": "ERROR", "logger": "zeka.openai_client", "message": "openai API anahtarı bulunamadı", "module": "openai_client", "function": "__init__", "line": 117}
{"timestamp": "2025-05-24T15:44:02.430404", "level": "ERROR", "logger": "zeka.openai_client", "message": "openai API anahtarı bulunamadı", "module": "openai_client", "function": "__init__", "line": 117}
{"timestamp": "2025-05-24T15:44:02.659938", "level": "ERROR", "logger": "zeka.openai_client", "message": "openai API anahtarı bulunamadı", "module": "openai_client", "function": "__init__", "line": 117}
{"timestamp": "2025-05-24T15:44:06.673564", "level": "ERROR", "logger": "zeka.openai_client", "message": "openai API anahtarı bulunamadı", "module": "openai_client", "function": "__init__", "line": 117}
{"timestamp": "2025-05-24T15:44:06.688787", "level": "ERROR", "logger": "zeka.openai_client", "message": "openai API anahtarı bulunamadı", "module": "openai_client", "function": "__init__", "line": 117}
{"timestamp": "2025-05-24T15:44:10.671215", "level": "ERROR", "logger": "zeka.openai_client", "message": "openai API anahtarı bulunamadı", "module": "openai_client", "function": "__init__", "line": 117}
{"timestamp": "2025-05-24T15:44:10.686749", "level": "ERROR", "logger": "zeka.openai_client", "message": "openai API anahtarı bulunamadı", "module": "openai_client", "function": "__init__", "line": 117}
{"timestamp": "2025-05-24T15:44:14.666953", "level": "ERROR", "logger": "zeka.openai_client", "message": "openai API anahtarı bulunamadı", "module": "openai_client", "function": "__init__", "line": 117}
{"timestamp": "2025-05-24T15:44:14.697351", "level": "ERROR", "logger": "zeka.openai_client", "message": "openai API anahtarı bulunamadı", "module": "openai_client", "function": "__init__", "line": 117}
{"timestamp": "2025-05-24T15:44:18.026576", "level": "ERROR", "logger": "zeka.openai_client", "message": "openai API anahtarı bulunamadı", "module": "openai_client", "function": "__init__", "line": 117}
{"timestamp": "2025-05-24T15:44:18.073376", "level": "ERROR", "logger": "zeka.openai_client", "message": "openai API anahtarı bulunamadı", "module": "openai_client", "function": "__init__", "line": 117}
{"timestamp": "2025-05-24T15:44:21.440479", "level": "ERROR", "logger": "zeka.openai_client", "message": "openai API anahtarı bulunamadı", "module": "openai_client", "function": "__init__", "line": 117}
{"timestamp": "2025-05-24T15:44:21.518157", "level": "ERROR", "logger": "zeka.openai_client", "message": "openai API anahtarı bulunamadı", "module": "openai_client", "function": "__init__", "line": 117}
{"timestamp": "2025-05-24T15:44:24.805668", "level": "ERROR", "logger": "zeka.openai_client", "message": "openai API anahtarı bulunamadı", "module": "openai_client", "function": "__init__", "line": 117}
{"timestamp": "2025-05-24T15:44:24.896783", "level": "ERROR", "logger": "zeka.openai_client", "message": "openai API anahtarı bulunamadı", "module": "openai_client", "function": "__init__", "line": 117}
