{"timestamp": "2025-05-22T21:11:35.140345", "level": "ERROR", "logger": "zeka.vector_database", "message": "Arama yapılırken hata: Collection.query() got an unexpected keyword argument 'include_embeddings'", "module": "vector_database", "function": "search", "line": 406, "exception": {"type": "TypeError", "message": "Collection.query() got an unexpected keyword argument 'include_embeddings'", "traceback": "Traceback (most recent call last):\n  File \"C:\\Users\\tpoyr\\OneDrive\\Masaüstü\\Yeni klasör\\src\\core\\vector_database.py\", line 385, in search\n    results = await asyncio.get_event_loop().run_in_executor(\n              ^^^^^^^^^^^^^^^^^^^^^^^^^^^^^^^^^^^^^^^^^^^^^^^\n        self.executor, _search\n        ^^^^^^^^^^^^^^^^^^^^^^\n    )\n    ^\n  File \"C:\\Users\\tpoyr\\AppData\\Local\\Programs\\Python\\Python313\\Lib\\concurrent\\futures\\thread.py\", line 59, in run\n    result = self.fn(*self.args, **self.kwargs)\n  File \"C:\\Users\\tpoyr\\OneDrive\\Masaüstü\\Yeni klasör\\src\\core\\vector_database.py\", line 374, in _search\n    return collection.query(\n           ~~~~~~~~~~~~~~~~^\n        query_texts=[query],\n        ^^^^^^^^^^^^^^^^^^^^\n    ...<4 lines>...\n        include_distances=include_distances\n        ^^^^^^^^^^^^^^^^^^^^^^^^^^^^^^^^^^^\n    )\n    ^\nTypeError: Collection.query() got an unexpected keyword argument 'include_embeddings'"}}
{"timestamp": "2025-05-22T21:12:01.533953", "level": "ERROR", "logger": "zeka.openrouter_client", "message": "Yeniden denenemeyen hata: object SyncPage[Model] can't be used in 'await' expression", "module": "openrouter_client", "function": "_retry_with_backoff", "line": 151, "exception": {"type": "TypeError", "message": "object SyncPage[Model] can't be used in 'await' expression", "traceback": "Traceback (most recent call last):\n  File \"C:\\Users\\tpoyr\\OneDrive\\Masaüstü\\Yeni klasör\\src\\core\\openrouter_client.py\", line 138, in _retry_with_backoff\n    return await func(*args, **kwargs)\n           ^^^^^^^^^^^^^^^^^^^^^^^^^^^\n  File \"C:\\Users\\tpoyr\\OneDrive\\Masaüstü\\Yeni klasör\\src\\core\\openrouter_client.py\", line 405, in _list_models\n    return await self.client.models.list()\n           ^^^^^^^^^^^^^^^^^^^^^^^^^^^^^^^\nTypeError: object SyncPage[Model] can't be used in 'await' expression"}}
{"timestamp": "2025-05-22T21:12:01.536989", "level": "ERROR", "logger": "zeka.openrouter_client", "message": "Model listesi alınamadı: object SyncPage[Model] can't be used in 'await' expression", "module": "openrouter_client", "function": "list_available_models", "line": 445, "exception": {"type": "TypeError", "message": "object SyncPage[Model] can't be used in 'await' expression", "traceback": "Traceback (most recent call last):\n  File \"C:\\Users\\tpoyr\\OneDrive\\Masaüstü\\Yeni klasör\\src\\core\\openrouter_client.py\", line 408, in list_available_models\n    response = await self._retry_with_backoff(_list_models)\n               ^^^^^^^^^^^^^^^^^^^^^^^^^^^^^^^^^^^^^^^^^^^^\n  File \"C:\\Users\\tpoyr\\OneDrive\\Masaüstü\\Yeni klasör\\src\\core\\openrouter_client.py\", line 138, in _retry_with_backoff\n    return await func(*args, **kwargs)\n           ^^^^^^^^^^^^^^^^^^^^^^^^^^^\n  File \"C:\\Users\\tpoyr\\OneDrive\\Masaüstü\\Yeni klasör\\src\\core\\openrouter_client.py\", line 405, in _list_models\n    return await self.client.models.list()\n           ^^^^^^^^^^^^^^^^^^^^^^^^^^^^^^^\nTypeError: object SyncPage[Model] can't be used in 'await' expression"}}
{"timestamp": "2025-05-22T21:12:45.179614", "level": "ERROR", "logger": "zeka.openrouter_client", "message": "Yeniden denenemeyen hata: object ChatCompletion can't be used in 'await' expression", "module": "openrouter_client", "function": "_retry_with_backoff", "line": 151, "exception": {"type": "TypeError", "message": "object ChatCompletion can't be used in 'await' expression", "traceback": "Traceback (most recent call last):\n  File \"C:\\Users\\tpoyr\\OneDrive\\Masaüstü\\Yeni klasör\\src\\core\\openrouter_client.py\", line 138, in _retry_with_backoff\n    return await func(*args, **kwargs)\n           ^^^^^^^^^^^^^^^^^^^^^^^^^^^\n  File \"C:\\Users\\tpoyr\\OneDrive\\Masaüstü\\Yeni klasör\\src\\core\\openrouter_client.py\", line 212, in _make_request\n    return await self.client.chat.completions.create(**params)\n           ^^^^^^^^^^^^^^^^^^^^^^^^^^^^^^^^^^^^^^^^^^^^^^^^^^^\nTypeError: object ChatCompletion can't be used in 'await' expression"}}
{"timestamp": "2025-05-22T21:12:45.182814", "level": "ERROR", "logger": "zeka.openrouter_client", "message": "OpenRouter API hatası: object ChatCompletion can't be used in 'await' expression", "module": "openrouter_client", "function": "generate_text", "line": 262, "exception": {"type": "TypeError", "message": "object ChatCompletion can't be used in 'await' expression", "traceback": "Traceback (most recent call last):\n  File \"C:\\Users\\tpoyr\\OneDrive\\Masaüstü\\Yeni klasör\\src\\core\\openrouter_client.py\", line 215, in generate_text\n    response = await self._retry_with_backoff(_make_request)\n               ^^^^^^^^^^^^^^^^^^^^^^^^^^^^^^^^^^^^^^^^^^^^^\n  File \"C:\\Users\\tpoyr\\OneDrive\\Masaüstü\\Yeni klasör\\src\\core\\openrouter_client.py\", line 138, in _retry_with_backoff\n    return await func(*args, **kwargs)\n           ^^^^^^^^^^^^^^^^^^^^^^^^^^^\n  File \"C:\\Users\\tpoyr\\OneDrive\\Masaüstü\\Yeni klasör\\src\\core\\openrouter_client.py\", line 212, in _make_request\n    return await self.client.chat.completions.create(**params)\n           ^^^^^^^^^^^^^^^^^^^^^^^^^^^^^^^^^^^^^^^^^^^^^^^^^^^\nTypeError: object ChatCompletion can't be used in 'await' expression"}}
{"timestamp": "2025-05-22T21:14:30.142292", "level": "ERROR", "logger": "zeka.openrouter_client", "message": "Yeniden denenemeyen hata: object ChatCompletion can't be used in 'await' expression", "module": "openrouter_client", "function": "_retry_with_backoff", "line": 151, "exception": {"type": "TypeError", "message": "object ChatCompletion can't be used in 'await' expression", "traceback": "Traceback (most recent call last):\n  File \"C:\\Users\\tpoyr\\OneDrive\\Masaüstü\\Yeni klasör\\src\\core\\openrouter_client.py\", line 138, in _retry_with_backoff\n    return await func(*args, **kwargs)\n           ^^^^^^^^^^^^^^^^^^^^^^^^^^^\n  File \"C:\\Users\\tpoyr\\OneDrive\\Masaüstü\\Yeni klasör\\src\\core\\openrouter_client.py\", line 212, in _make_request\n    return await self.client.chat.completions.create(**params)\n           ^^^^^^^^^^^^^^^^^^^^^^^^^^^^^^^^^^^^^^^^^^^^^^^^^^^\nTypeError: object ChatCompletion can't be used in 'await' expression"}}
{"timestamp": "2025-05-22T21:14:30.146084", "level": "ERROR", "logger": "zeka.openrouter_client", "message": "OpenRouter API hatası: object ChatCompletion can't be used in 'await' expression", "module": "openrouter_client", "function": "generate_text", "line": 262, "exception": {"type": "TypeError", "message": "object ChatCompletion can't be used in 'await' expression", "traceback": "Traceback (most recent call last):\n  File \"C:\\Users\\tpoyr\\OneDrive\\Masaüstü\\Yeni klasör\\src\\core\\openrouter_client.py\", line 215, in generate_text\n    response = await self._retry_with_backoff(_make_request)\n               ^^^^^^^^^^^^^^^^^^^^^^^^^^^^^^^^^^^^^^^^^^^^^\n  File \"C:\\Users\\tpoyr\\OneDrive\\Masaüstü\\Yeni klasör\\src\\core\\openrouter_client.py\", line 138, in _retry_with_backoff\n    return await func(*args, **kwargs)\n           ^^^^^^^^^^^^^^^^^^^^^^^^^^^\n  File \"C:\\Users\\tpoyr\\OneDrive\\Masaüstü\\Yeni klasör\\src\\core\\openrouter_client.py\", line 212, in _make_request\n    return await self.client.chat.completions.create(**params)\n           ^^^^^^^^^^^^^^^^^^^^^^^^^^^^^^^^^^^^^^^^^^^^^^^^^^^\nTypeError: object ChatCompletion can't be used in 'await' expression"}}
{"timestamp": "2025-05-22T21:17:27.742619", "level": "ERROR", "logger": "zeka.vector_database", "message": "Arama yapılırken hata: Collection.query() got an unexpected keyword argument 'include_embeddings'", "module": "vector_database", "function": "search", "line": 406, "exception": {"type": "TypeError", "message": "Collection.query() got an unexpected keyword argument 'include_embeddings'", "traceback": "Traceback (most recent call last):\n  File \"C:\\Users\\tpoyr\\OneDrive\\Masaüstü\\Yeni klasör\\src\\core\\vector_database.py\", line 385, in search\n    results = await asyncio.get_event_loop().run_in_executor(\n              ^^^^^^^^^^^^^^^^^^^^^^^^^^^^^^^^^^^^^^^^^^^^^^^\n        self.executor, _search\n        ^^^^^^^^^^^^^^^^^^^^^^\n    )\n    ^\n  File \"C:\\Users\\tpoyr\\AppData\\Local\\Programs\\Python\\Python313\\Lib\\concurrent\\futures\\thread.py\", line 59, in run\n    result = self.fn(*self.args, **self.kwargs)\n  File \"C:\\Users\\tpoyr\\OneDrive\\Masaüstü\\Yeni klasör\\src\\core\\vector_database.py\", line 374, in _search\n    return collection.query(\n           ~~~~~~~~~~~~~~~~^\n        query_texts=[query],\n        ^^^^^^^^^^^^^^^^^^^^\n    ...<4 lines>...\n        include_distances=include_distances\n        ^^^^^^^^^^^^^^^^^^^^^^^^^^^^^^^^^^^\n    )\n    ^\nTypeError: Collection.query() got an unexpected keyword argument 'include_embeddings'"}}
{"timestamp": "2025-05-22T21:18:53.036748", "level": "ERROR", "logger": "zeka.vector_database", "message": "Arama yapılırken hata: Collection.query() got an unexpected keyword argument 'include_distances'", "module": "vector_database", "function": "search", "line": 404, "exception": {"type": "TypeError", "message": "Collection.query() got an unexpected keyword argument 'include_distances'", "traceback": "Traceback (most recent call last):\n  File \"C:\\Users\\tpoyr\\OneDrive\\Masaüstü\\Yeni klasör\\src\\core\\vector_database.py\", line 383, in search\n    results = await asyncio.get_event_loop().run_in_executor(\n              ^^^^^^^^^^^^^^^^^^^^^^^^^^^^^^^^^^^^^^^^^^^^^^^\n        self.executor, _search\n        ^^^^^^^^^^^^^^^^^^^^^^\n    )\n    ^\n  File \"C:\\Users\\tpoyr\\AppData\\Local\\Programs\\Python\\Python313\\Lib\\concurrent\\futures\\thread.py\", line 59, in run\n    result = self.fn(*self.args, **self.kwargs)\n  File \"C:\\Users\\tpoyr\\OneDrive\\Masaüstü\\Yeni klasör\\src\\core\\vector_database.py\", line 373, in _search\n    return collection.query(\n           ~~~~~~~~~~~~~~~~^\n        query_texts=[query],\n        ^^^^^^^^^^^^^^^^^^^^\n    ...<3 lines>...\n        include_distances=include_distances\n        ^^^^^^^^^^^^^^^^^^^^^^^^^^^^^^^^^^^\n    )\n    ^\nTypeError: Collection.query() got an unexpected keyword argument 'include_distances'"}}
{"timestamp": "2025-05-22T21:25:41.358329", "level": "ERROR", "logger": "zeka.zeka_assistant", "message": "Ajanlar kaydedilirken hata: 'UserProfile' object has no attribute 'get_access_interface'", "module": "main", "function": "_register_agents", "line": 160, "exception": {"type": "AttributeError", "message": "'UserProfile' object has no attribute 'get_access_interface'", "traceback": "Traceback (most recent call last):\n  File \"C:\\Users\\tpoyr\\OneDrive\\Masaüstü\\Yeni klasör\\src\\main.py\", line 112, in _register_agents\n    conversation_agent.set_user_profile_access(self.user_profile.get_access_interface())\n                                               ^^^^^^^^^^^^^^^^^^^^^^^^^^^^^^^^^^^^^^\nAttributeError: 'UserProfile' object has no attribute 'get_access_interface'"}}
{"timestamp": "2025-05-22T21:25:41.362393", "level": "ERROR", "logger": "zeka.zeka_assistant", "message": "ZEKA Asistanı başlatılırken hata: [ZEKA_ERROR] Ajanlar kaydedilemedi: 'UserProfile' object has no attribute 'get_access_interface'", "module": "main", "function": "initialize", "line": 89, "exception": {"type": "ZEKAError", "message": "[ZEKA_ERROR] Ajanlar kaydedilemedi: 'UserProfile' object has no attribute 'get_access_interface'", "traceback": "Traceback (most recent call last):\n  File \"C:\\Users\\tpoyr\\OneDrive\\Masaüstü\\Yeni klasör\\src\\main.py\", line 112, in _register_agents\n    conversation_agent.set_user_profile_access(self.user_profile.get_access_interface())\n                                               ^^^^^^^^^^^^^^^^^^^^^^^^^^^^^^^^^^^^^^\nAttributeError: 'UserProfile' object has no attribute 'get_access_interface'\n\nDuring handling of the above exception, another exception occurred:\n\nTraceback (most recent call last):\n  File \"C:\\Users\\tpoyr\\OneDrive\\Masaüstü\\Yeni klasör\\src\\main.py\", line 80, in initialize\n    await self._register_agents()\n  File \"C:\\Users\\tpoyr\\OneDrive\\Masaüstü\\Yeni klasör\\src\\main.py\", line 161, in _register_agents\n    raise ZEKAError(f\"Ajanlar kaydedilemedi: {str(e)}\")\nsrc.core.exceptions.ZEKAError: [ZEKA_ERROR] Ajanlar kaydedilemedi: 'UserProfile' object has no attribute 'get_access_interface'"}}
{"timestamp": "2025-05-22T21:26:49.963261", "level": "ERROR", "logger": "zeka.zeka_assistant", "message": "Ajanlar kaydedilirken hata: CalendarAgent.__init__() takes 1 positional argument but 4 were given", "module": "main", "function": "_register_agents", "line": 160, "exception": {"type": "TypeError", "message": "CalendarAgent.__init__() takes 1 positional argument but 4 were given", "traceback": "Traceback (most recent call last):\n  File \"C:\\Users\\tpoyr\\OneDrive\\Masaüstü\\Yeni klasör\\src\\main.py\", line 122, in _register_agents\n    calendar_agent = CalendarAgent(\"calendar_agent\", \"Takvim Ajanı\", \"Takvim ve toplantı yönetimi\")\n                     ~~~~~~~~~~~~~^^^^^^^^^^^^^^^^^^^^^^^^^^^^^^^^^^^^^^^^^^^^^^^^^^^^^^^^^^^^^^^^^\nTypeError: CalendarAgent.__init__() takes 1 positional argument but 4 were given"}}
{"timestamp": "2025-05-22T21:26:49.967651", "level": "ERROR", "logger": "zeka.zeka_assistant", "message": "ZEKA Asistanı başlatılırken hata: [ZEKA_ERROR] Ajanlar kaydedilemedi: CalendarAgent.__init__() takes 1 positional argument but 4 were given", "module": "main", "function": "initialize", "line": 89, "exception": {"type": "ZEKAError", "message": "[ZEKA_ERROR] Ajanlar kaydedilemedi: CalendarAgent.__init__() takes 1 positional argument but 4 were given", "traceback": "Traceback (most recent call last):\n  File \"C:\\Users\\tpoyr\\OneDrive\\Masaüstü\\Yeni klasör\\src\\main.py\", line 122, in _register_agents\n    calendar_agent = CalendarAgent(\"calendar_agent\", \"Takvim Ajanı\", \"Takvim ve toplantı yönetimi\")\n                     ~~~~~~~~~~~~~^^^^^^^^^^^^^^^^^^^^^^^^^^^^^^^^^^^^^^^^^^^^^^^^^^^^^^^^^^^^^^^^^\nTypeError: CalendarAgent.__init__() takes 1 positional argument but 4 were given\n\nDuring handling of the above exception, another exception occurred:\n\nTraceback (most recent call last):\n  File \"C:\\Users\\tpoyr\\OneDrive\\Masaüstü\\Yeni klasör\\src\\main.py\", line 80, in initialize\n    await self._register_agents()\n  File \"C:\\Users\\tpoyr\\OneDrive\\Masaüstü\\Yeni klasör\\src\\main.py\", line 161, in _register_agents\n    raise ZEKAError(f\"Ajanlar kaydedilemedi: {str(e)}\")\nsrc.core.exceptions.ZEKAError: [ZEKA_ERROR] Ajanlar kaydedilemedi: CalendarAgent.__init__() takes 1 positional argument but 4 were given"}}
{"timestamp": "2025-05-22T21:28:44.716478", "level": "ERROR", "logger": "zeka.zeka_assistant", "message": "ZEKA Asistanı başlatılırken hata: name 'user_id' is not defined", "module": "main", "function": "initialize", "line": 89, "exception": {"type": "NameError", "message": "name 'user_id' is not defined", "traceback": "Traceback (most recent call last):\n  File \"C:\\Users\\tpoyr\\OneDrive\\Masaüstü\\Yeni klasör\\src\\main.py\", line 86, in initialize\n    print(f\"ZEKA Asistanı başlatıldı. Kullanıcı: {user_id}\")\n                                                  ^^^^^^^\nNameError: name 'user_id' is not defined"}}
{"timestamp": "2025-05-22T21:29:36.447858", "level": "ERROR", "logger": "zeka.zeka_assistant", "message": "ZEKA Asistanı başlatılırken hata: 'ZEKAAssistant' object has no attribute 'user_id'", "module": "main", "function": "initialize", "line": 89, "exception": {"type": "AttributeError", "message": "'ZEKAAssistant' object has no attribute 'user_id'", "traceback": "Traceback (most recent call last):\n  File \"C:\\Users\\tpoyr\\OneDrive\\Masaüstü\\Yeni klasör\\src\\main.py\", line 86, in initialize\n    print(f\"ZEKA Asistanı başlatıldı. Kullanıcı: {self.user_id}\")\n                                                  ^^^^^^^^^^^^\nAttributeError: 'ZEKAAssistant' object has no attribute 'user_id'"}}
{"timestamp": "2025-05-22T21:31:04.267973", "level": "ERROR", "logger": "zeka.orchestrator", "message": "MCP ile analiz sırasında hata: MCP sunucusuna bağlanılamadı: Resmi MCP Sunucusu", "module": "orchestrator", "function": "_analyze_with_mcp", "line": 309, "exception": {"type": "ConnectionError", "message": "MCP sunucusuna bağlanılamadı: Resmi MCP Sunucusu", "traceback": "Traceback (most recent call last):\n  File \"C:\\Users\\tpoyr\\OneDrive\\Masaüstü\\Yeni klasör\\src\\core\\orchestrator.py\", line 292, in _analyze_with_mcp\n    response = await self.mcp_manager.send_request(\n               ^^^^^^^^^^^^^^^^^^^^^^^^^^^^^^^^^^^^\n    ...<5 lines>...\n    )\n    ^\n  File \"C:\\Users\\tpoyr\\OneDrive\\Masaüstü\\Yeni klasör\\src\\core\\mcp_manager.py\", line 540, in send_request\n    raise ConnectionError(f\"MCP sunucusuna bağlanılamadı: {server.name}\")\nConnectionError: MCP sunucusuna bağlanılamadı: Resmi MCP Sunucusu"}}
{"timestamp": "2025-05-22T21:32:04.318726", "level": "ERROR", "logger": "zeka.orchestrator", "message": "İstek işlenirken hata oluştu (60.19s): İstek zaman aşımına uğradı: 249a6be7-72b1-4818-8200-4e6679a09933", "module": "orchestrator", "function": "process_request", "line": 221, "exception": {"type": "TimeoutError", "message": "İstek zaman aşımına uğradı: 249a6be7-72b1-4818-8200-4e6679a09933", "traceback": "Traceback (most recent call last):\n  File \"C:\\Users\\tpoyr\\OneDrive\\Masaüstü\\Yeni klasör\\src\\core\\orchestrator.py\", line 187, in process_request\n    raise TimeoutError(f\"İstek zaman aşımına uğradı: {task.id}\")\nTimeoutError: İstek zaman aşımına uğradı: 249a6be7-72b1-4818-8200-4e6679a09933"}}
{"timestamp": "2025-05-22T21:32:04.330551", "level": "ERROR", "logger": "zeka.orchestrator", "message": "MCP ile analiz sırasında hata: MCP sunucusuna bağlanılamadı: Resmi MCP Sunucusu", "module": "orchestrator", "function": "_analyze_with_mcp", "line": 309, "exception": {"type": "ConnectionError", "message": "MCP sunucusuna bağlanılamadı: Resmi MCP Sunucusu", "traceback": "Traceback (most recent call last):\n  File \"C:\\Users\\tpoyr\\OneDrive\\Masaüstü\\Yeni klasör\\src\\core\\orchestrator.py\", line 292, in _analyze_with_mcp\n    response = await self.mcp_manager.send_request(\n               ^^^^^^^^^^^^^^^^^^^^^^^^^^^^^^^^^^^^\n    ...<5 lines>...\n    )\n    ^\n  File \"C:\\Users\\tpoyr\\OneDrive\\Masaüstü\\Yeni klasör\\src\\core\\mcp_manager.py\", line 540, in send_request\n    raise ConnectionError(f\"MCP sunucusuna bağlanılamadı: {server.name}\")\nConnectionError: MCP sunucusuna bağlanılamadı: Resmi MCP Sunucusu"}}
{"timestamp": "2025-05-22T21:33:04.386181", "level": "ERROR", "logger": "zeka.orchestrator", "message": "İstek işlenirken hata oluştu (60.06s): İstek zaman aşımına uğradı: f1729ce1-6ce8-45c0-b7f2-49309fc16292", "module": "orchestrator", "function": "process_request", "line": 221, "exception": {"type": "TimeoutError", "message": "İstek zaman aşımına uğradı: f1729ce1-6ce8-45c0-b7f2-49309fc16292", "traceback": "Traceback (most recent call last):\n  File \"C:\\Users\\tpoyr\\OneDrive\\Masaüstü\\Yeni klasör\\src\\core\\orchestrator.py\", line 187, in process_request\n    raise TimeoutError(f\"İstek zaman aşımına uğradı: {task.id}\")\nTimeoutError: İstek zaman aşımına uğradı: f1729ce1-6ce8-45c0-b7f2-49309fc16292"}}
{"timestamp": "2025-05-22T21:33:04.396050", "level": "ERROR", "logger": "zeka.orchestrator", "message": "MCP ile analiz sırasında hata: MCP sunucusuna bağlanılamadı: Resmi MCP Sunucusu", "module": "orchestrator", "function": "_analyze_with_mcp", "line": 309, "exception": {"type": "ConnectionError", "message": "MCP sunucusuna bağlanılamadı: Resmi MCP Sunucusu", "traceback": "Traceback (most recent call last):\n  File \"C:\\Users\\tpoyr\\OneDrive\\Masaüstü\\Yeni klasör\\src\\core\\orchestrator.py\", line 292, in _analyze_with_mcp\n    response = await self.mcp_manager.send_request(\n               ^^^^^^^^^^^^^^^^^^^^^^^^^^^^^^^^^^^^\n    ...<5 lines>...\n    )\n    ^\n  File \"C:\\Users\\tpoyr\\OneDrive\\Masaüstü\\Yeni klasör\\src\\core\\mcp_manager.py\", line 540, in send_request\n    raise ConnectionError(f\"MCP sunucusuna bağlanılamadı: {server.name}\")\nConnectionError: MCP sunucusuna bağlanılamadı: Resmi MCP Sunucusu"}}
{"timestamp": "2025-05-22T21:34:29.986692", "level": "ERROR", "logger": "zeka.orchestrator", "message": "MCP ile analiz sırasında hata: MCP sunucusuna bağlanılamadı: Resmi MCP Sunucusu", "module": "orchestrator", "function": "_analyze_with_mcp", "line": 309, "exception": {"type": "ConnectionError", "message": "MCP sunucusuna bağlanılamadı: Resmi MCP Sunucusu", "traceback": "Traceback (most recent call last):\n  File \"C:\\Users\\tpoyr\\OneDrive\\Masaüstü\\Yeni klasör\\src\\core\\orchestrator.py\", line 292, in _analyze_with_mcp\n    response = await self.mcp_manager.send_request(\n               ^^^^^^^^^^^^^^^^^^^^^^^^^^^^^^^^^^^^\n    ...<5 lines>...\n    )\n    ^\n  File \"C:\\Users\\tpoyr\\OneDrive\\Masaüstü\\Yeni klasör\\src\\core\\mcp_manager.py\", line 540, in send_request\n    raise ConnectionError(f\"MCP sunucusuna bağlanılamadı: {server.name}\")\nConnectionError: MCP sunucusuna bağlanılamadı: Resmi MCP Sunucusu"}}
{"timestamp": "2025-05-22T21:35:30.075168", "level": "ERROR", "logger": "zeka.orchestrator", "message": "İstek işlenirken hata oluştu (60.11s): İstek zaman aşımına uğradı: 60e4821d-766f-4867-a70c-4aaf11bc989f", "module": "orchestrator", "function": "process_request", "line": 221, "exception": {"type": "TimeoutError", "message": "İstek zaman aşımına uğradı: 60e4821d-766f-4867-a70c-4aaf11bc989f", "traceback": "Traceback (most recent call last):\n  File \"C:\\Users\\tpoyr\\OneDrive\\Masaüstü\\Yeni klasör\\src\\core\\orchestrator.py\", line 187, in process_request\n    raise TimeoutError(f\"İstek zaman aşımına uğradı: {task.id}\")\nTimeoutError: İstek zaman aşımına uğradı: 60e4821d-766f-4867-a70c-4aaf11bc989f"}}
{"timestamp": "2025-05-22T21:37:24.757240", "level": "ERROR", "logger": "zeka.orchestrator", "message": "MCP ile analiz sırasında hata: MCP sunucusuna bağlanılamadı: Resmi MCP Sunucusu", "module": "orchestrator", "function": "_analyze_with_mcp", "line": 309, "exception": {"type": "ConnectionError", "message": "MCP sunucusuna bağlanılamadı: Resmi MCP Sunucusu", "traceback": "Traceback (most recent call last):\n  File \"C:\\Users\\tpoyr\\OneDrive\\Masaüstü\\Yeni klasör\\src\\core\\orchestrator.py\", line 292, in _analyze_with_mcp\n    response = await self.mcp_manager.send_request(\n               ^^^^^^^^^^^^^^^^^^^^^^^^^^^^^^^^^^^^\n    ...<5 lines>...\n    )\n    ^\n  File \"C:\\Users\\tpoyr\\OneDrive\\Masaüstü\\Yeni klasör\\src\\core\\mcp_manager.py\", line 540, in send_request\n    raise ConnectionError(f\"MCP sunucusuna bağlanılamadı: {server.name}\")\nConnectionError: MCP sunucusuna bağlanılamadı: Resmi MCP Sunucusu"}}
{"timestamp": "2025-05-22T21:37:24.765149", "level": "ERROR", "logger": "zeka.memory_manager", "message": "Vektör arama sırasında hata: argument of type 'coroutine' is not iterable", "module": "memory_manager", "function": "retrieve", "line": 200, "exception": {"type": "TypeError", "message": "argument of type 'coroutine' is not iterable", "traceback": "Traceback (most recent call last):\n  File \"C:\\Users\\tpoyr\\OneDrive\\Masaüstü\\Yeni klasör\\src\\core\\memory_manager.py\", line 196, in retrieve\n    vector_results = await self._search_vector_db(query, limit)\n                     ^^^^^^^^^^^^^^^^^^^^^^^^^^^^^^^^^^^^^^^^^^\n  File \"C:\\Users\\tpoyr\\OneDrive\\Masaüstü\\Yeni klasör\\src\\core\\memory_manager.py\", line 331, in _search_vector_db\n    if results and \"metadatas\" in results and results[\"metadatas\"]:\n                   ^^^^^^^^^^^^^^^^^^^^^^\nTypeError: argument of type 'coroutine' is not iterable"}}
{"timestamp": "2025-05-22T21:38:24.841447", "level": "ERROR", "logger": "zeka.orchestrator", "message": "İstek işlenirken hata oluştu (60.09s): İstek zaman aşımına uğradı: 7352346e-70c3-40db-9272-1d1f1d989c09", "module": "orchestrator", "function": "process_request", "line": 221, "exception": {"type": "TimeoutError", "message": "İstek zaman aşımına uğradı: 7352346e-70c3-40db-9272-1d1f1d989c09", "traceback": "Traceback (most recent call last):\n  File \"C:\\Users\\tpoyr\\OneDrive\\Masaüstü\\Yeni klasör\\src\\core\\orchestrator.py\", line 187, in process_request\n    raise TimeoutError(f\"İstek zaman aşımına uğradı: {task.id}\")\nTimeoutError: İstek zaman aşımına uğradı: 7352346e-70c3-40db-9272-1d1f1d989c09"}}
{"timestamp": "2025-05-22T21:43:27.413970", "level": "ERROR", "logger": "zeka.orchestrator", "message": "MCP ile analiz sırasında hata: MCP sunucusuna bağlanılamadı: Resmi MCP Sunucusu", "module": "orchestrator", "function": "_analyze_with_mcp", "line": 309, "exception": {"type": "ConnectionError", "message": "MCP sunucusuna bağlanılamadı: Resmi MCP Sunucusu", "traceback": "Traceback (most recent call last):\n  File \"C:\\Users\\tpoyr\\OneDrive\\Masaüstü\\Yeni klasör\\src\\core\\orchestrator.py\", line 292, in _analyze_with_mcp\n    response = await self.mcp_manager.send_request(\n               ^^^^^^^^^^^^^^^^^^^^^^^^^^^^^^^^^^^^\n    ...<5 lines>...\n    )\n    ^\n  File \"C:\\Users\\tpoyr\\OneDrive\\Masaüstü\\Yeni klasör\\src\\core\\mcp_manager.py\", line 540, in send_request\n    raise ConnectionError(f\"MCP sunucusuna bağlanılamadı: {server.name}\")\nConnectionError: MCP sunucusuna bağlanılamadı: Resmi MCP Sunucusu"}}
{"timestamp": "2025-05-22T21:43:37.857740", "level": "ERROR", "logger": "zeka.vector_database", "message": "Belgeler eklenirken hata: Expected metadata value to be a str, int, float, bool, or None, got {'task_id': '0819dec3-61d7-480d-b5d8-0039715be4c9', 'language': 'Genel sohbet ve iletişim', 'style': 'neutral', 'action': 'chat', 'intent': 'general'} which is a dict in add.", "module": "vector_database", "function": "add_documents", "line": 341, "exception": {"type": "ValueError", "message": "Expected metadata value to be a str, int, float, bool, or None, got {'task_id': '0819dec3-61d7-480d-b5d8-0039715be4c9', 'language': 'Genel sohbet ve iletişim', 'style': 'neutral', 'action': 'chat', 'intent': 'general'} which is a dict in add.", "traceback": "Traceback (most recent call last):\n  File \"C:\\Users\\tpoyr\\OneDrive\\Masaüstü\\Yeni klasör\\src\\core\\vector_database.py\", line 332, in add_documents\n    await asyncio.get_event_loop().run_in_executor(\n        self.executor, _add_documents\n    )\n  File \"C:\\Users\\tpoyr\\AppData\\Local\\Programs\\Python\\Python313\\Lib\\concurrent\\futures\\thread.py\", line 59, in run\n    result = self.fn(*self.args, **self.kwargs)\n  File \"C:\\Users\\tpoyr\\OneDrive\\Masaüstü\\Yeni klasör\\src\\core\\vector_database.py\", line 325, in _add_documents\n    return collection.add(\n           ~~~~~~~~~~~~~~^\n        documents=documents,\n        ^^^^^^^^^^^^^^^^^^^^\n        metadatas=metadatas,\n        ^^^^^^^^^^^^^^^^^^^^\n        ids=ids\n        ^^^^^^^\n    )\n    ^\n  File \"C:\\Users\\tpoyr\\AppData\\Local\\Programs\\Python\\Python313\\Lib\\site-packages\\chromadb\\api\\models\\Collection.py\", line 80, in add\n    add_request = self._validate_and_prepare_add_request(\n        ids=ids,\n    ...<4 lines>...\n        uris=uris,\n    )\n  File \"C:\\Users\\tpoyr\\AppData\\Local\\Programs\\Python\\Python313\\Lib\\site-packages\\chromadb\\api\\models\\CollectionCommon.py\", line 95, in wrapper\n    return func(self, *args, **kwargs)\n  File \"C:\\Users\\tpoyr\\AppData\\Local\\Programs\\Python\\Python313\\Lib\\site-packages\\chromadb\\api\\models\\CollectionCommon.py\", line 230, in _validate_and_prepare_add_request\n    validate_insert_record_set(record_set=add_records)\n    ~~~~~~~~~~~~~~~~~~~~~~~~~~^^^^^^^^^^^^^^^^^^^^^^^^\n  File \"C:\\Users\\tpoyr\\AppData\\Local\\Programs\\Python\\Python313\\Lib\\site-packages\\chromadb\\api\\types.py\", line 250, in validate_insert_record_set\n    validate_metadatas(record_set[\"metadatas\"])\n    ~~~~~~~~~~~~~~~~~~^^^^^^^^^^^^^^^^^^^^^^^^^\n  File \"C:\\Users\\tpoyr\\AppData\\Local\\Programs\\Python\\Python313\\Lib\\site-packages\\chromadb\\api\\types.py\", line 727, in validate_metadatas\n    validate_metadata(metadata)\n    ~~~~~~~~~~~~~~~~~^^^^^^^^^^\n  File \"C:\\Users\\tpoyr\\AppData\\Local\\Programs\\Python\\Python313\\Lib\\site-packages\\chromadb\\api\\types.py\", line 693, in validate_metadata\n    raise ValueError(\n        f\"Expected metadata value to be a str, int, float, bool, or None, got {value} which is a {type(value).__name__}\"\n    )\nValueError: Expected metadata value to be a str, int, float, bool, or None, got {'task_id': '0819dec3-61d7-480d-b5d8-0039715be4c9', 'language': 'Genel sohbet ve iletişim', 'style': 'neutral', 'action': 'chat', 'intent': 'general'} which is a dict in add."}}
{"timestamp": "2025-05-22T21:43:37.877655", "level": "ERROR", "logger": "zeka.memory_manager", "message": "Etkileşim vektör veritabanına kaydedilirken hata: [VECTORDB_ERROR] Belgeler eklenemedi: Expected metadata value to be a str, int, float, bool, or None, got {'task_id': '0819dec3-61d7-480d-b5d8-0039715be4c9', 'language': 'Genel sohbet ve iletişim', 'style': 'neutral', 'action': 'chat', 'intent': 'general'} which is a dict in add.", "module": "memory_manager", "function": "_store_to_vector_db", "line": 189, "exception": {"type": "VectorDBError", "message": "[VECTORDB_ERROR] Belgeler eklenemedi: Expected metadata value to be a str, int, float, bool, or None, got {'task_id': '0819dec3-61d7-480d-b5d8-0039715be4c9', 'language': 'Genel sohbet ve iletişim', 'style': 'neutral', 'action': 'chat', 'intent': 'general'} which is a dict in add.", "traceback": "Traceback (most recent call last):\n  File \"C:\\Users\\tpoyr\\OneDrive\\Masaüstü\\Yeni klasör\\src\\core\\vector_database.py\", line 332, in add_documents\n    await asyncio.get_event_loop().run_in_executor(\n        self.executor, _add_documents\n    )\n  File \"C:\\Users\\tpoyr\\AppData\\Local\\Programs\\Python\\Python313\\Lib\\concurrent\\futures\\thread.py\", line 59, in run\n    result = self.fn(*self.args, **self.kwargs)\n  File \"C:\\Users\\tpoyr\\OneDrive\\Masaüstü\\Yeni klasör\\src\\core\\vector_database.py\", line 325, in _add_documents\n    return collection.add(\n           ~~~~~~~~~~~~~~^\n        documents=documents,\n        ^^^^^^^^^^^^^^^^^^^^\n        metadatas=metadatas,\n        ^^^^^^^^^^^^^^^^^^^^\n        ids=ids\n        ^^^^^^^\n    )\n    ^\n  File \"C:\\Users\\tpoyr\\AppData\\Local\\Programs\\Python\\Python313\\Lib\\site-packages\\chromadb\\api\\models\\Collection.py\", line 80, in add\n    add_request = self._validate_and_prepare_add_request(\n        ids=ids,\n    ...<4 lines>...\n        uris=uris,\n    )\n  File \"C:\\Users\\tpoyr\\AppData\\Local\\Programs\\Python\\Python313\\Lib\\site-packages\\chromadb\\api\\models\\CollectionCommon.py\", line 95, in wrapper\n    return func(self, *args, **kwargs)\n  File \"C:\\Users\\tpoyr\\AppData\\Local\\Programs\\Python\\Python313\\Lib\\site-packages\\chromadb\\api\\models\\CollectionCommon.py\", line 230, in _validate_and_prepare_add_request\n    validate_insert_record_set(record_set=add_records)\n    ~~~~~~~~~~~~~~~~~~~~~~~~~~^^^^^^^^^^^^^^^^^^^^^^^^\n  File \"C:\\Users\\tpoyr\\AppData\\Local\\Programs\\Python\\Python313\\Lib\\site-packages\\chromadb\\api\\types.py\", line 250, in validate_insert_record_set\n    validate_metadatas(record_set[\"metadatas\"])\n    ~~~~~~~~~~~~~~~~~~^^^^^^^^^^^^^^^^^^^^^^^^^\n  File \"C:\\Users\\tpoyr\\AppData\\Local\\Programs\\Python\\Python313\\Lib\\site-packages\\chromadb\\api\\types.py\", line 727, in validate_metadatas\n    validate_metadata(metadata)\n    ~~~~~~~~~~~~~~~~~^^^^^^^^^^\n  File \"C:\\Users\\tpoyr\\AppData\\Local\\Programs\\Python\\Python313\\Lib\\site-packages\\chromadb\\api\\types.py\", line 693, in validate_metadata\n    raise ValueError(\n        f\"Expected metadata value to be a str, int, float, bool, or None, got {value} which is a {type(value).__name__}\"\n    )\nValueError: Expected metadata value to be a str, int, float, bool, or None, got {'task_id': '0819dec3-61d7-480d-b5d8-0039715be4c9', 'language': 'Genel sohbet ve iletişim', 'style': 'neutral', 'action': 'chat', 'intent': 'general'} which is a dict in add.\n\nDuring handling of the above exception, another exception occurred:\n\nTraceback (most recent call last):\n  File \"C:\\Users\\tpoyr\\OneDrive\\Masaüstü\\Yeni klasör\\src\\core\\memory_manager.py\", line 179, in _store_to_vector_db\n    await self.vector_db.add_documents(\n    ...<4 lines>...\n    )\n  File \"C:\\Users\\tpoyr\\OneDrive\\Masaüstü\\Yeni klasör\\src\\core\\vector_database.py\", line 342, in add_documents\n    raise VectorDBError(f\"Belgeler eklenemedi: {str(e)}\")\nsrc.core.exceptions.VectorDBError: [VECTORDB_ERROR] Belgeler eklenemedi: Expected metadata value to be a str, int, float, bool, or None, got {'task_id': '0819dec3-61d7-480d-b5d8-0039715be4c9', 'language': 'Genel sohbet ve iletişim', 'style': 'neutral', 'action': 'chat', 'intent': 'general'} which is a dict in add."}}
{"timestamp": "2025-05-22T21:44:27.496387", "level": "ERROR", "logger": "zeka.orchestrator", "message": "İstek işlenirken hata oluştu (60.09s): İstek zaman aşımına uğradı: 0819dec3-61d7-480d-b5d8-0039715be4c9", "module": "orchestrator", "function": "process_request", "line": 221, "exception": {"type": "TimeoutError", "message": "İstek zaman aşımına uğradı: 0819dec3-61d7-480d-b5d8-0039715be4c9", "traceback": "Traceback (most recent call last):\n  File \"C:\\Users\\tpoyr\\OneDrive\\Masaüstü\\Yeni klasör\\src\\core\\orchestrator.py\", line 187, in process_request\n    raise TimeoutError(f\"İstek zaman aşımına uğradı: {task.id}\")\nTimeoutError: İstek zaman aşımına uğradı: 0819dec3-61d7-480d-b5d8-0039715be4c9"}}
{"timestamp": "2025-05-22T21:51:28.340987", "level": "ERROR", "logger": "zeka.orchestrator", "message": "MCP ile analiz sırasında hata: MCP sunucusuna bağlanılamadı: Resmi MCP Sunucusu", "module": "orchestrator", "function": "_analyze_with_mcp", "line": 309, "exception": {"type": "ConnectionError", "message": "MCP sunucusuna bağlanılamadı: Resmi MCP Sunucusu", "traceback": "Traceback (most recent call last):\n  File \"C:\\Users\\tpoyr\\OneDrive\\Masaüstü\\Yeni klasör\\src\\core\\orchestrator.py\", line 292, in _analyze_with_mcp\n    response = await self.mcp_manager.send_request(\n               ^^^^^^^^^^^^^^^^^^^^^^^^^^^^^^^^^^^^\n    ...<5 lines>...\n    )\n    ^\n  File \"C:\\Users\\tpoyr\\OneDrive\\Masaüstü\\Yeni klasör\\src\\core\\mcp_manager.py\", line 540, in send_request\n    raise ConnectionError(f\"MCP sunucusuna bağlanılamadı: {server.name}\")\nConnectionError: MCP sunucusuna bağlanılamadı: Resmi MCP Sunucusu"}}
{"timestamp": "2025-05-22T21:52:28.429071", "level": "ERROR", "logger": "zeka.orchestrator", "message": "İstek işlenirken hata oluştu (60.09s): İstek zaman aşımına uğradı: bc9ab01c-0f6f-4526-ae35-1ceeac86799c", "module": "orchestrator", "function": "process_request", "line": 221, "exception": {"type": "TimeoutError", "message": "İstek zaman aşımına uğradı: bc9ab01c-0f6f-4526-ae35-1ceeac86799c", "traceback": "Traceback (most recent call last):\n  File \"C:\\Users\\tpoyr\\OneDrive\\Masaüstü\\Yeni klasör\\src\\core\\orchestrator.py\", line 187, in process_request\n    raise TimeoutError(f\"İstek zaman aşımına uğradı: {task.id}\")\nTimeoutError: İstek zaman aşımına uğradı: bc9ab01c-0f6f-4526-ae35-1ceeac86799c"}}
{"timestamp": "2025-05-22T22:02:26.551336", "level": "ERROR", "logger": "zeka.orchestrator", "message": "İstek işlenirken hata oluştu (180.04s): İstek zaman aşımına uğradı: 91becebc-e7e9-4171-94b8-1e1eec368b76", "module": "orchestrator", "function": "process_request", "line": 221, "exception": {"type": "TimeoutError", "message": "İstek zaman aşımına uğradı: 91becebc-e7e9-4171-94b8-1e1eec368b76", "traceback": "Traceback (most recent call last):\n  File \"C:\\Users\\tpoyr\\OneDrive\\Masaüstü\\Yeni klasör\\src\\core\\orchestrator.py\", line 187, in process_request\n    raise TimeoutError(f\"İstek zaman aşımına uğradı: {task.id}\")\nTimeoutError: İstek zaman aşımına uğradı: 91becebc-e7e9-4171-94b8-1e1eec368b76"}}
{"timestamp": "2025-05-22T22:07:49.049948", "level": "ERROR", "logger": "zeka.zeka_assistant", "message": "Ajanlar kaydedilirken hata: 'CalendarAgent' object has no attribute 'set_language_model'", "module": "main", "function": "_register_agents", "line": 185, "exception": {"type": "AttributeError", "message": "'CalendarAgent' object has no attribute 'set_language_model'", "traceback": "Traceback (most recent call last):\n  File \"C:\\Users\\tpoyr\\OneDrive\\Masaüstü\\Yeni klasör\\src\\main.py\", line 148, in _register_agents\n    calendar_agent.set_language_model(openrouter_client)  # Dil modelini ayarla\n    ^^^^^^^^^^^^^^^^^^^^^^^^^^^^^^^^^\nAttributeError: 'CalendarAgent' object has no attribute 'set_language_model'"}}
{"timestamp": "2025-05-22T22:07:49.053092", "level": "ERROR", "logger": "zeka.zeka_assistant", "message": "ZEKA Asistanı başlatılırken hata: [ZEKA_ERROR] Ajanlar kaydedilemedi: 'CalendarAgent' object has no attribute 'set_language_model'", "module": "main", "function": "initialize", "line": 92, "exception": {"type": "ZEKAError", "message": "[ZEKA_ERROR] Ajanlar kaydedilemedi: 'CalendarAgent' object has no attribute 'set_language_model'", "traceback": "Traceback (most recent call last):\n  File \"C:\\Users\\tpoyr\\OneDrive\\Masaüstü\\Yeni klasör\\src\\main.py\", line 148, in _register_agents\n    calendar_agent.set_language_model(openrouter_client)  # Dil modelini ayarla\n    ^^^^^^^^^^^^^^^^^^^^^^^^^^^^^^^^^\nAttributeError: 'CalendarAgent' object has no attribute 'set_language_model'\n\nDuring handling of the above exception, another exception occurred:\n\nTraceback (most recent call last):\n  File \"C:\\Users\\tpoyr\\OneDrive\\Masaüstü\\Yeni klasör\\src\\main.py\", line 83, in initialize\n    await self._register_agents()\n  File \"C:\\Users\\tpoyr\\OneDrive\\Masaüstü\\Yeni klasör\\src\\main.py\", line 186, in _register_agents\n    raise ZEKAError(f\"Ajanlar kaydedilemedi: {str(e)}\")\nsrc.core.exceptions.ZEKAError: [ZEKA_ERROR] Ajanlar kaydedilemedi: 'CalendarAgent' object has no attribute 'set_language_model'"}}
{"timestamp": "2025-05-22T22:12:25.744209", "level": "ERROR", "logger": "zeka.orchestrator", "message": "İstek işlenirken hata oluştu (180.23s): İstek zaman aşımına uğradı: 6b3c92ae-726e-4a57-a56b-172271266eb8", "module": "orchestrator", "function": "process_request", "line": 221, "exception": {"type": "TimeoutError", "message": "İstek zaman aşımına uğradı: 6b3c92ae-726e-4a57-a56b-172271266eb8", "traceback": "Traceback (most recent call last):\n  File \"C:\\Users\\tpoyr\\OneDrive\\Masaüstü\\Yeni klasör\\src\\core\\orchestrator.py\", line 187, in process_request\n    raise TimeoutError(f\"İstek zaman aşımına uğradı: {task.id}\")\nTimeoutError: İstek zaman aşımına uğradı: 6b3c92ae-726e-4a57-a56b-172271266eb8"}}
{"timestamp": "2025-05-22T22:16:58.665579", "level": "ERROR", "logger": "zeka.orchestrator", "message": "İstek işlenirken hata oluştu (180.08s): İstek zaman aşımına uğradı: db5a8eb7-0aee-4031-b1d0-4b6b5f52ac97", "module": "orchestrator", "function": "process_request", "line": 233, "exception": {"type": "TimeoutError", "message": "İstek zaman aşımına uğradı: db5a8eb7-0aee-4031-b1d0-4b6b5f52ac97", "traceback": "Traceback (most recent call last):\n  File \"C:\\Users\\tpoyr\\OneDrive\\Masaüstü\\Yeni klasör\\src\\core\\orchestrator.py\", line 187, in process_request\n    raise TimeoutError(f\"İstek zaman aşımına uğradı: {task.id}\")\nTimeoutError: İstek zaman aşımına uğradı: db5a8eb7-0aee-4031-b1d0-4b6b5f52ac97"}}
{"timestamp": "2025-05-22T22:37:29.182697", "level": "ERROR", "logger": "zeka.orchestrator", "message": "İstek işlenirken hata oluştu (13.09s): MemoryManager.store_interaction() missing 1 required positional argument: 'system_response'", "module": "orchestrator", "function": "process_request", "line": 251, "exception": {"type": "TypeError", "message": "MemoryManager.store_interaction() missing 1 required positional argument: 'system_response'", "traceback": "Traceback (most recent call last):\n  File \"C:\\Users\\tpoyr\\OneDrive\\Masaüstü\\Yeni klasör\\src\\core\\orchestrator.py\", line 229, in process_request\n    await self.memory_manager.store_interaction(interaction)\n          ~~~~~~~~~~~~~~~~~~~~~~~~~~~~~~~~~~~~~^^^^^^^^^^^^^\nTypeError: MemoryManager.store_interaction() missing 1 required positional argument: 'system_response'"}}
